Workbook

Sheet Read me
A1: The numbers behind the figure pairs of work/wf-reproduction (Fuchs et al. 2024, arXiv:2405.02709, Figures 4 to 10, against ours).
A3: Paper columns: the paper's curves read off the PDF's vector paths (digitise_paper.py), each panel calibrated from its tick labels (residuals below 1e-6 of the axis range); the paper's lines are sampled every 2 mm and are interpolated linearly to our radii. Figure 8 is a raster image in the PDF and has no paper column.
A4: Ours columns: WarpFactory at the published live script's configuration (W1_Warp_Shell.mlx: R1 = 10 m, R2 = 20 m, M = 4.49e27 kg, smoothFactor 4000, 300 x 300 x 5 cells at 0.2 m), the Part 1 export, read on the grid column at x = -0.1 m (the grid has no x = 0 column); the two outermost cells are dropped. Static shell for Figures 4 to 7, shift 0.02 for Figures 8 to 10.
A5: Replica columns: the construction rebuilt in NumPy (work/shell/replicate_profiles.py, validated against WarpFactory to 1e-13) at the smoothing fitted to the paper's own smoothed inputs: density span 6100 samples, pressure span 3540 (ratio 1.72, the paper's footnote 7), where the live script uses 7160 and 4000 (ratio 1.79). Only quantities that follow from the 1D construction have this column: the smoothed inputs, the radial pressure, the tangential pressure by the equilibrium identity, g00 and g22.
A6: Difference and ratio columns are formulas; Excel computes them when the file opens. Units: J/m^3 for every stress-energy quantity (energy density times c^2, momentum density times c), metric components dimensionless, r in metres.
A8: What the numbers show: the paper's and our curves have the same shape at the same radii in every panel; the paper's amplitudes are 1 to 11 % higher, most where the feature is sharpest, and the replica at the fitted smoothing reproduces the paper's values (hoop-stress spike to 0.07 %, wall width to 2 mm, g22 peak to 0.08 %). The published live script is therefore not the exact configuration behind the figures (register row C10); the physics is unchanged. Write-up: work/wf-reproduction/RESULTS.md.
A10: Sheets: Summary (extrema per curve, RMS and maximum differences); Fig 4 to Fig 10; Smoothing fit; Part 2 exact vs sampled (work/matrix/run-fine/exact_cases.csv: warpax's exact margins against WarpFactory's sampled maps, Part 2).
A11: Built 27 October 2026 by work/wf-reproduction/make_workbook.py. Paper figures: CC BY 4.0.

Sheet Summary
A1: Sheet | B1: Curve | C1: Paper: max | D1: Ours: max | E1: max ratio paper / ours | F1: Paper: min | G1: Ours: min | H1: RMS difference / max of ours | I1: Largest |difference| / max of ours | J1: Replica at the figures' smoothing: max | K1: Replica max / paper max
A2: Fig 4 | B2: rho' before smoothing (x c^2) | C2: =MAX('Fig 4'!B3:B150) | D2: =MAX('Fig 4'!C3:C150) | E2: =C2/D2 | F2: =MIN('Fig 4'!B3:B150) | G2: =MIN('Fig 4'!C3:C150) | H2: =SQRT(SUMPRODUCT(('Fig 4'!D3:D150)^2)/COUNT('Fig 4'!D3:D150))/MAX('Fig 4'!C3:C150) | I2: =MAX(MAX('Fig 4'!D3:D150),-MIN('Fig 4'!D3:D150))/MAX('Fig 4'!C3:C150)
A3: Fig 4 | B3: rho~ smoothed (x c^2) | C3: =MAX('Fig 4'!F3:F150) | D3: =MAX('Fig 4'!G3:G150) | E3: =C3/D3 | F3: =MIN('Fig 4'!F3:F150) | G3: =MIN('Fig 4'!G3:G150) | H3: =SQRT(SUMPRODUCT(('Fig 4'!H3:H150)^2)/COUNT('Fig 4'!H3:H150))/MAX('Fig 4'!G3:G150) | I3: =MAX(MAX('Fig 4'!H3:H150),-MIN('Fig 4'!H3:H150))/MAX('Fig 4'!G3:G150) | J3: =MAX('Fig 4'!J3:J150) | K3: =J3/C3
A4: Fig 4 | B4: P' before smoothing | C4: =MAX('Fig 4'!K3:K150) | D4: =MAX('Fig 4'!L3:L150) | E4: =C4/D4 | F4: =MIN('Fig 4'!K3:K150) | G4: =MIN('Fig 4'!L3:L150) | H4: =SQRT(SUMPRODUCT(('Fig 4'!M3:M150)^2)/COUNT('Fig 4'!M3:M150))/MAX('Fig 4'!L3:L150) | I4: =MAX(MAX('Fig 4'!M3:M150),-MIN('Fig 4'!M3:M150))/MAX('Fig 4'!L3:L150)
A5: Fig 4 | B5: P~ smoothed | C5: =MAX('Fig 4'!O3:O150) | D5: =MAX('Fig 4'!P3:P150) | E5: =C5/D5 | F5: =MIN('Fig 4'!O3:O150) | G5: =MIN('Fig 4'!P3:P150) | H5: =SQRT(SUMPRODUCT(('Fig 4'!Q3:Q150)^2)/COUNT('Fig 4'!Q3:Q150))/MAX('Fig 4'!P3:P150) | I5: =MAX(MAX('Fig 4'!Q3:Q150),-MIN('Fig 4'!Q3:Q150))/MAX('Fig 4'!P3:P150) | J5: =MAX('Fig 4'!S3:S150) | K5: =J5/C5
A6: Fig 5 | B6: g00 shell | C6: =MAX('Fig 5'!B3:B150) | D6: =MAX('Fig 5'!C3:C150) | E6: =C6/D6 | F6: =MIN('Fig 5'!B3:B150) | G6: =MIN('Fig 5'!C3:C150) | H6: =SQRT(SUMPRODUCT(('Fig 5'!D3:D150)^2)/COUNT('Fig 5'!D3:D150))/MAX('Fig 5'!C3:C150) | I6: =MAX(MAX('Fig 5'!D3:D150),-MIN('Fig 5'!D3:D150))/MAX('Fig 5'!C3:C150) | J6: =MAX('Fig 5'!F3:F150) | K6: =J6/C6
A7: Fig 5 | B7: g22 shell | C7: =MAX('Fig 5'!G3:G150) | D7: =MAX('Fig 5'!H3:H150) | E7: =C7/D7 | F7: =MIN('Fig 5'!G3:G150) | G7: =MIN('Fig 5'!H3:H150) | H7: =SQRT(SUMPRODUCT(('Fig 5'!I3:I150)^2)/COUNT('Fig 5'!I3:I150))/MAX('Fig 5'!H3:H150) | I7: =MAX(MAX('Fig 5'!I3:I150),-MIN('Fig 5'!I3:I150))/MAX('Fig 5'!H3:H150) | J7: =MAX('Fig 5'!K3:K150) | K7: =J7/C7
A8: Fig 5 | B8: g00 Schwarzschild | C8: =MAX('Fig 5'!L3:L150) | D8: =MAX('Fig 5'!M3:M150) | E8: =C8/D8 | F8: =MIN('Fig 5'!L3:L150) | G8: =MIN('Fig 5'!M3:M150) | H8: =SQRT(SUMPRODUCT(('Fig 5'!N3:N150)^2)/COUNT('Fig 5'!N3:N150))/MAX('Fig 5'!M3:M150) | I8: =MAX(MAX('Fig 5'!N3:N150),-MIN('Fig 5'!N3:N150))/MAX('Fig 5'!M3:M150)
A9: Fig 5 | B9: g22 Schwarzschild | C9: =MAX('Fig 5'!P3:P150) | D9: =MAX('Fig 5'!Q3:Q150) | E9: =C9/D9 | F9: =MIN('Fig 5'!P3:P150) | G9: =MIN('Fig 5'!Q3:Q150) | H9: =SQRT(SUMPRODUCT(('Fig 5'!R3:R150)^2)/COUNT('Fig 5'!R3:R150))/MAX('Fig 5'!Q3:Q150) | I9: =MAX(MAX('Fig 5'!R3:R150),-MIN('Fig 5'!R3:R150))/MAX('Fig 5'!Q3:Q150)
A10: Fig 6 | B10: energy density rho | C10: =MAX('Fig 6'!B3:B150) | D10: =MAX('Fig 6'!C3:C150) | E10: =C10/D10 | F10: =MIN('Fig 6'!B3:B150) | G10: =MIN('Fig 6'!C3:C150) | H10: =SQRT(SUMPRODUCT(('Fig 6'!D3:D150)^2)/COUNT('Fig 6'!D3:D150))/MAX('Fig 6'!C3:C150) | I10: =MAX(MAX('Fig 6'!D3:D150),-MIN('Fig 6'!D3:D150))/MAX('Fig 6'!C3:C150)
A11: Fig 6 | B11: rho~ smoothed input (x c^2) | C11: =MAX('Fig 6'!F3:F150) | D11: =MAX('Fig 6'!G3:G150) | E11: =C11/D11 | F11: =MIN('Fig 6'!F3:F150) | G11: =MIN('Fig 6'!G3:G150) | H11: =SQRT(SUMPRODUCT(('Fig 6'!H3:H150)^2)/COUNT('Fig 6'!H3:H150))/MAX('Fig 6'!G3:G150) | I11: =MAX(MAX('Fig 6'!H3:H150),-MIN('Fig 6'!H3:H150))/MAX('Fig 6'!G3:G150) | J11: =MAX('Fig 6'!J3:J150) | K11: =J11/C11
A12: Fig 6 | B12: P_2 radial | C12: =MAX('Fig 6'!K3:K150) | D12: =MAX('Fig 6'!L3:L150) | E12: =C12/D12 | F12: =MIN('Fig 6'!K3:K150) | G12: =MIN('Fig 6'!L3:L150) | H12: =SQRT(SUMPRODUCT(('Fig 6'!M3:M150)^2)/COUNT('Fig 6'!M3:M150))/MAX('Fig 6'!L3:L150) | I12: =MAX(MAX('Fig 6'!M3:M150),-MIN('Fig 6'!M3:M150))/MAX('Fig 6'!L3:L150) | J12: =MAX('Fig 6'!O3:O150) | K12: =J12/C12
A13: Fig 6 | B13: P_1 = P_3 tangential | C13: =MAX('Fig 6'!P3:P150) | D13: =MAX('Fig 6'!Q3:Q150) | E13: =C13/D13 | F13: =MIN('Fig 6'!P3:P150) | G13: =MIN('Fig 6'!Q3:Q150) | H13: =SQRT(SUMPRODUCT(('Fig 6'!R3:R150)^2)/COUNT('Fig 6'!R3:R150))/MAX('Fig 6'!Q3:Q150) | I13: =MAX(MAX('Fig 6'!R3:R150),-MIN('Fig 6'!R3:R150))/MAX('Fig 6'!Q3:Q150) | J13: =MAX('Fig 6'!T3:T150) | K13: =J13/C13
A14: Fig 6 | B14: P~ smoothed input | C14: =MAX('Fig 6'!U3:U150) | D14: =MAX('Fig 6'!V3:V150) | E14: =C14/D14 | F14: =MIN('Fig 6'!U3:U150) | G14: =MIN('Fig 6'!V3:V150) | H14: =SQRT(SUMPRODUCT(('Fig 6'!W3:W150)^2)/COUNT('Fig 6'!W3:W150))/MAX('Fig 6'!V3:V150) | I14: =MAX(MAX('Fig 6'!W3:W150),-MIN('Fig 6'!W3:W150))/MAX('Fig 6'!V3:V150) | J14: =MAX('Fig 6'!Y3:Y150) | K14: =J14/C14
A15: Fig 7 | B15: Null | C15: =MAX('Fig 7'!B3:B150) | D15: =MAX('Fig 7'!C3:C150) | E15: =C15/D15 | F15: =MIN('Fig 7'!B3:B150) | G15: =MIN('Fig 7'!C3:C150) | H15: =SQRT(SUMPRODUCT(('Fig 7'!D3:D150)^2)/COUNT('Fig 7'!D3:D150))/MAX('Fig 7'!C3:C150) | I15: =MAX(MAX('Fig 7'!D3:D150),-MIN('Fig 7'!D3:D150))/MAX('Fig 7'!C3:C150)
A16: Fig 7 | B16: Weak | C16: =MAX('Fig 7'!F3:F150) | D16: =MAX('Fig 7'!G3:G150) | E16: =C16/D16 | F16: =MIN('Fig 7'!F3:F150) | G16: =MIN('Fig 7'!G3:G150) | H16: =SQRT(SUMPRODUCT(('Fig 7'!H3:H150)^2)/COUNT('Fig 7'!H3:H150))/MAX('Fig 7'!G3:G150) | I16: =MAX(MAX('Fig 7'!H3:H150),-MIN('Fig 7'!H3:H150))/MAX('Fig 7'!G3:G150)
A17: Fig 7 | B17: Strong | C17: =MAX('Fig 7'!J3:J150) | D17: =MAX('Fig 7'!K3:K150) | E17: =C17/D17 | F17: =MIN('Fig 7'!J3:J150) | G17: =MIN('Fig 7'!K3:K150) | H17: =SQRT(SUMPRODUCT(('Fig 7'!L3:L150)^2)/COUNT('Fig 7'!L3:L150))/MAX('Fig 7'!K3:K150) | I17: =MAX(MAX('Fig 7'!L3:L150),-MIN('Fig 7'!L3:L150))/MAX('Fig 7'!K3:K150)
A18: Fig 7 | B18: Dominant | C18: =MAX('Fig 7'!N3:N150) | D18: =MAX('Fig 7'!O3:O150) | E18: =C18/D18 | F18: =MIN('Fig 7'!N3:N150) | G18: =MIN('Fig 7'!O3:O150) | H18: =SQRT(SUMPRODUCT(('Fig 7'!P3:P150)^2)/COUNT('Fig 7'!P3:P150))/MAX('Fig 7'!O3:O150) | I18: =MAX(MAX('Fig 7'!P3:P150),-MIN('Fig 7'!P3:P150))/MAX('Fig 7'!O3:O150)
A19: Fig 7 | B19: Null, consistent metric | D19: =MAX('Fig 7'!S3:S150) | G19: =MIN('Fig 7'!S3:S150)
A20: Fig 7 | B20: Weak, consistent metric | D20: =MAX('Fig 7'!W3:W150) | G20: =MIN('Fig 7'!W3:W150)
A21: Fig 8 | B21: g00 | D21: =MAX('Fig 8'!C3:C150) | G21: =MIN('Fig 8'!C3:C150)
A22: Fig 8 | B22: g01 | D22: =MAX('Fig 8'!G3:G150) | G22: =MIN('Fig 8'!G3:G150)
A23: Fig 8 | B23: g22 | D23: =MAX('Fig 8'!K3:K150) | G23: =MIN('Fig 8'!K3:K150)
A24: Fig 9 | B24: energy density rho | C24: =MAX('Fig 9'!B3:B150) | D24: =MAX('Fig 9'!C3:C150) | E24: =C24/D24 | F24: =MIN('Fig 9'!B3:B150) | G24: =MIN('Fig 9'!C3:C150) | H24: =SQRT(SUMPRODUCT(('Fig 9'!D3:D150)^2)/COUNT('Fig 9'!D3:D150))/MAX('Fig 9'!C3:C150) | I24: =MAX(MAX('Fig 9'!D3:D150),-MIN('Fig 9'!D3:D150))/MAX('Fig 9'!C3:C150)
A25: Fig 9 | B25: P_2 radial | C25: =MAX('Fig 9'!F3:F150) | D25: =MAX('Fig 9'!G3:G150) | E25: =C25/D25 | F25: =MIN('Fig 9'!F3:F150) | G25: =MIN('Fig 9'!G3:G150) | H25: =SQRT(SUMPRODUCT(('Fig 9'!H3:H150)^2)/COUNT('Fig 9'!H3:H150))/MAX('Fig 9'!G3:G150) | I25: =MAX(MAX('Fig 9'!H3:H150),-MIN('Fig 9'!H3:H150))/MAX('Fig 9'!G3:G150)
A26: Fig 9 | B26: P_1 | C26: =MAX('Fig 9'!J3:J150) | D26: =MAX('Fig 9'!K3:K150) | E26: =C26/D26 | F26: =MIN('Fig 9'!J3:J150) | G26: =MIN('Fig 9'!K3:K150) | H26: =SQRT(SUMPRODUCT(('Fig 9'!L3:L150)^2)/COUNT('Fig 9'!L3:L150))/MAX('Fig 9'!K3:K150) | I26: =MAX(MAX('Fig 9'!L3:L150),-MIN('Fig 9'!L3:L150))/MAX('Fig 9'!K3:K150)
A27: Fig 9 | B27: P_3 | C27: =MAX('Fig 9'!N3:N150) | D27: =MAX('Fig 9'!O3:O150) | E27: =C27/D27 | F27: =MIN('Fig 9'!N3:N150) | G27: =MIN('Fig 9'!O3:O150) | H27: =SQRT(SUMPRODUCT(('Fig 9'!P3:P150)^2)/COUNT('Fig 9'!P3:P150))/MAX('Fig 9'!O3:O150) | I27: =MAX(MAX('Fig 9'!P3:P150),-MIN('Fig 9'!P3:P150))/MAX('Fig 9'!O3:O150)
A28: Fig 9 | B28: momentum p_1 (x c) | C28: =MAX('Fig 9'!R3:R150) | D28: =MAX('Fig 9'!S3:S150) | E28: =C28/D28 | F28: =MIN('Fig 9'!R3:R150) | G28: =MIN('Fig 9'!S3:S150) | H28: =SQRT(SUMPRODUCT(('Fig 9'!T3:T150)^2)/COUNT('Fig 9'!T3:T150))/MAX('Fig 9'!S3:S150) | I28: =MAX(MAX('Fig 9'!T3:T150),-MIN('Fig 9'!T3:T150))/MAX('Fig 9'!S3:S150)
A29: Fig 9 | B29: momentum p_2 = p_3 (x c) | C29: =MAX('Fig 9'!V3:V150) | D29: =MAX('Fig 9'!W3:W150) | E29: =C29/D29 | F29: =MIN('Fig 9'!V3:V150) | G29: =MIN('Fig 9'!W3:W150) | H29: =SQRT(SUMPRODUCT(('Fig 9'!X3:X150)^2)/COUNT('Fig 9'!X3:X150))/MAX('Fig 9'!W3:W150) | I29: =MAX(MAX('Fig 9'!X3:X150),-MIN('Fig 9'!X3:X150))/MAX('Fig 9'!W3:W150)
A30: Fig 9 | B30: shear sigma_12 | C30: =MAX('Fig 9'!Z3:Z150) | D30: =MAX('Fig 9'!AA3:AA150) | E30: =C30/D30 | F30: =MIN('Fig 9'!Z3:Z150) | G30: =MIN('Fig 9'!AA3:AA150) | H30: =SQRT(SUMPRODUCT(('Fig 9'!AB3:AB150)^2)/COUNT('Fig 9'!AB3:AB150))/MAX('Fig 9'!AA3:AA150) | I30: =MAX(MAX('Fig 9'!AB3:AB150),-MIN('Fig 9'!AB3:AB150))/MAX('Fig 9'!AA3:AA150)
A31: Fig 10 | B31: Null | C31: =MAX('Fig 10'!B3:B150) | D31: =MAX('Fig 10'!C3:C150) | E31: =C31/D31 | F31: =MIN('Fig 10'!B3:B150) | G31: =MIN('Fig 10'!C3:C150) | H31: =SQRT(SUMPRODUCT(('Fig 10'!D3:D150)^2)/COUNT('Fig 10'!D3:D150))/MAX('Fig 10'!C3:C150) | I31: =MAX(MAX('Fig 10'!D3:D150),-MIN('Fig 10'!D3:D150))/MAX('Fig 10'!C3:C150)
A32: Fig 10 | B32: Weak | C32: =MAX('Fig 10'!F3:F150) | D32: =MAX('Fig 10'!G3:G150) | E32: =C32/D32 | F32: =MIN('Fig 10'!F3:F150) | G32: =MIN('Fig 10'!G3:G150) | H32: =SQRT(SUMPRODUCT(('Fig 10'!H3:H150)^2)/COUNT('Fig 10'!H3:H150))/MAX('Fig 10'!G3:G150) | I32: =MAX(MAX('Fig 10'!H3:H150),-MIN('Fig 10'!H3:H150))/MAX('Fig 10'!G3:G150)
A33: Fig 10 | B33: Strong | C33: =MAX('Fig 10'!J3:J150) | D33: =MAX('Fig 10'!K3:K150) | E33: =C33/D33 | F33: =MIN('Fig 10'!J3:J150) | G33: =MIN('Fig 10'!K3:K150) | H33: =SQRT(SUMPRODUCT(('Fig 10'!L3:L150)^2)/COUNT('Fig 10'!L3:L150))/MAX('Fig 10'!K3:K150) | I33: =MAX(MAX('Fig 10'!L3:L150),-MIN('Fig 10'!L3:L150))/MAX('Fig 10'!K3:K150)
A34: Fig 10 | B34: Dominant | C34: =MAX('Fig 10'!N3:N150) | D34: =MAX('Fig 10'!O3:O150) | E34: =C34/D34 | F34: =MIN('Fig 10'!N3:N150) | G34: =MIN('Fig 10'!O3:O150) | H34: =SQRT(SUMPRODUCT(('Fig 10'!P3:P150)^2)/COUNT('Fig 10'!P3:P150))/MAX('Fig 10'!O3:O150) | I34: =MAX(MAX('Fig 10'!P3:P150),-MIN('Fig 10'!P3:P150))/MAX('Fig 10'!O3:O150)
A35: Fig 10 | B35: Null, consistent metric | D35: =MAX('Fig 10'!S3:S150) | G35: =MIN('Fig 10'!S3:S150)
A36: Fig 10 | B36: Weak, consistent metric | D36: =MAX('Fig 10'!W3:W150) | G36: =MIN('Fig 10'!W3:W150)
A38: Ratios above 1 mean the paper's curve is larger. The 'replica at the figures' smoothing' column is the construction rebuilt at the spans fitted to the paper's inputs; where it is within a few tenths of a percent of the paper's maximum, the difference between the paper and ours is the smoothing and nothing else. Formulas reference the figure sheets; Excel evaluates them on opening.

Sheet Fig 4
A1: Figure 4: the construction's inputs before and after smoothing. Paper: digitised. Ours: profiles_f1.csv of the Part 1 run (the 1D construction at smoothFactor 4000). Replica: the same construction at the fitted spans 6100 / 3540.
A2: r [m] | B2: rho' before smoothing (x c^2): paper | C2: rho' before smoothing (x c^2): ours | D2: difference (paper - ours) | E2: ratio paper / ours | F2: rho~ smoothed (x c^2): paper | G2: rho~ smoothed (x c^2): ours | H2: difference (paper - ours) | I2: ratio paper / ours | J2: rho~ smoothed (x c^2): replica at the figures' smoothing | K2: P' before smoothing: paper | L2: P' before smoothing: ours | M2: difference (paper - ours) | N2: ratio paper / ours | O2: P~ smoothed: paper | P2: P~ smoothed: ours | Q2: difference (paper - ours) | R2: ratio paper / ours | S2: P~ smoothed: replica at the figures' smoothing
A3: 0.1 | B3: 1.737878e+37 | C3: 0 | D3: =B3-C3 | E3: =IF(ABS(C3)<1E-300,"",B3/C3) | F3: 1.737878e+37 | G3: 0 | H3: =F3-G3 | I3: =IF(ABS(G3)<1E-300,"",F3/G3) | J3: 0 | K3: 1.737878e+36 | L3: 0 | M3: =K3-L3 | N3: =IF(ABS(L3)<1E-300,"",K3/L3) | O3: 1.737878e+36 | P3: 0 | Q3: =O3-P3 | R3: =IF(ABS(P3)<1E-300,"",O3/P3) | S3: 0
A4: 0.3 | B4: 1.737878e+37 | C4: 0 | D4: =B4-C4 | E4: =IF(ABS(C4)<1E-300,"",B4/C4) | F4: 1.737878e+37 | G4: 0 | H4: =F4-G4 | I4: =IF(ABS(G4)<1E-300,"",F4/G4) | J4: 0 | K4: 1.737878e+36 | L4: 0 | M4: =K4-L4 | N4: =IF(ABS(L4)<1E-300,"",K4/L4) | O4: 1.738433e+36 | P4: 0 | Q4: =O4-P4 | R4: =IF(ABS(P4)<1E-300,"",O4/P4) | S4: 0
A5: 0.5 | B5: 1.737878e+37 | C5: 0 | D5: =B5-C5 | E5: =IF(ABS(C5)<1E-300,"",B5/C5) | F5: 1.737878e+37 | G5: 0 | H5: =F5-G5 | I5: =IF(ABS(G5)<1E-300,"",F5/G5) | J5: 0 | K5: 1.737878e+36 | L5: 0 | M5: =K5-L5 | N5: =IF(ABS(L5)<1E-300,"",K5/L5) | O5: 1.7384052e+36 | P5: 0 | Q5: =O5-P5 | R5: =IF(ABS(P5)<1E-300,"",O5/P5) | S5: 0
A6: 0.7 | B6: 1.737878e+37 | C6: 0 | D6: =B6-C6 | E6: =IF(ABS(C6)<1E-300,"",B6/C6) | F6: 1.737878e+37 | G6: 0 | H6: =F6-G6 | I6: =IF(ABS(G6)<1E-300,"",F6/G6) | J6: 0 | K6: 1.737878e+36 | L6: 0 | M6: =K6-L6 | N6: =IF(ABS(L6)<1E-300,"",K6/L6) | O6: 1.7373776e+36 | P6: 0 | Q6: =O6-P6 | R6: =IF(ABS(P6)<1E-300,"",O6/P6) | S6: 0
A7: 0.9 | B7: 1.737878e+37 | C7: 0 | D7: =B7-C7 | E7: =IF(ABS(C7)<1E-300,"",B7/C7) | F7: 1.737878e+37 | G7: 0 | H7: =F7-G7 | I7: =IF(ABS(G7)<1E-300,"",F7/G7) | J7: 0 | K7: 1.737878e+36 | L7: 0 | M7: =K7-L7 | N7: =IF(ABS(L7)<1E-300,"",K7/L7) | O7: 1.7373776e+36 | P7: 0 | Q7: =O7-P7 | R7: =IF(ABS(P7)<1E-300,"",O7/P7) | S7: 0
A8: 1.1 | B8: 1.737878e+37 | C8: 0 | D8: =B8-C8 | E8: =IF(ABS(C8)<1E-300,"",B8/C8) | F8: 1.737878e+37 | G8: 0 | H8: =F8-G8 | I8: =IF(ABS(G8)<1E-300,"",F8/G8) | J8: 0 | K8: 1.737878e+36 | L8: 0 | M8: =K8-L8 | N8: =IF(ABS(L8)<1E-300,"",K8/L8) | O8: 1.7374054e+36 | P8: 0 | Q8: =O8-P8 | R8: =IF(ABS(P8)<1E-300,"",O8/P8) | S8: 0
A9: 1.3 | B9: 1.737878e+37 | C9: 0 | D9: =B9-C9 | E9: =IF(ABS(C9)<1E-300,"",B9/C9) | F9: 1.737878e+37 | G9: 0 | H9: =F9-G9 | I9: =IF(ABS(G9)<1E-300,"",F9/G9) | J9: 0 | K9: 1.737878e+36 | L9: 0 | M9: =K9-L9 | N9: =IF(ABS(L9)<1E-300,"",K9/L9) | O9: 1.7374886e+36 | P9: 0 | Q9: =O9-P9 | R9: =IF(ABS(P9)<1E-300,"",O9/P9) | S9: 0
A10: 1.5 | B10: 1.737878e+37 | C10: 0 | D10: =B10-C10 | E10: =IF(ABS(C10)<1E-300,"",B10/C10) | F10: 1.737878e+37 | G10: 0 | H10: =F10-G10 | I10: =IF(ABS(G10)<1E-300,"",F10/G10) | J10: 0 | K10: 1.737878e+36 | L10: 0 | M10: =K10-L10 | N10: =IF(ABS(L10)<1E-300,"",K10/L10) | O10: 1.7381002e+36 | P10: 0 | Q10: =O10-P10 | R10: =IF(ABS(P10)<1E-300,"",O10/P10) | S10: 0
A11: 1.7 | B11: 1.737878e+37 | C11: 0 | D11: =B11-C11 | E11: =IF(ABS(C11)<1E-300,"",B11/C11) | F11: 1.737878e+37 | G11: 0 | H11: =F11-G11 | I11: =IF(ABS(G11)<1E-300,"",F11/G11) | J11: 0 | K11: 1.737878e+36 | L11: 0 | M11: =K11-L11 | N11: =IF(ABS(L11)<1E-300,"",K11/L11) | O11: 1.737878e+36 | P11: 0 | Q11: =O11-P11 | R11: =IF(ABS(P11)<1E-300,"",O11/P11) | S11: 0
A12: 1.9 | B12: 1.737878e+37 | C12: 0 | D12: =B12-C12 | E12: =IF(ABS(C12)<1E-300,"",B12/C12) | F12: 1.737878e+37 | G12: 0 | H12: =F12-G12 | I12: =IF(ABS(G12)<1E-300,"",F12/G12) | J12: 0 | K12: 1.737878e+36 | L12: 0 | M12: =K12-L12 | N12: =IF(ABS(L12)<1E-300,"",K12/L12) | O12: 1.737878e+36 | P12: 0 | Q12: =O12-P12 | R12: =IF(ABS(P12)<1E-300,"",O12/P12) | S12: 0
A13: 2.1 | B13: 1.737878e+37 | C13: 0 | D13: =B13-C13 | E13: =IF(ABS(C13)<1E-300,"",B13/C13) | F13: 1.737878e+37 | G13: 0 | H13: =F13-G13 | I13: =IF(ABS(G13)<1E-300,"",F13/G13) | J13: 0 | K13: 1.737878e+36 | L13: 0 | M13: =K13-L13 | N13: =IF(ABS(L13)<1E-300,"",K13/L13) | O13: 1.738433e+36 | P13: 0 | Q13: =O13-P13 | R13: =IF(ABS(P13)<1E-300,"",O13/P13) | S13: 0
A14: 2.3 | B14: 1.737878e+37 | C14: 0 | D14: =B14-C14 | E14: =IF(ABS(C14)<1E-300,"",B14/C14) | F14: 1.737878e+37 | G14: 0 | H14: =F14-G14 | I14: =IF(ABS(G14)<1E-300,"",F14/G14) | J14: 0 | K14: 1.737878e+36 | L14: 0 | M14: =K14-L14 | N14: =IF(ABS(L14)<1E-300,"",K14/L14) | O14: 1.737878e+36 | P14: 0 | Q14: =O14-P14 | R14: =IF(ABS(P14)<1E-300,"",O14/P14) | S14: 0
... A150: 29.5 | B150: 1.737878e+37 | C150: 0 | D150: =B150-C150 | E150: =IF(ABS(C150)<1E-300,"",B150/C150) | F150: 1.737878e+37 | G150: 0 | H150: =F150-G150 | I150: =IF(ABS(G150)<1E-300,"",F150/G150) | J150: 0 | K150: 1.737878e+36 | L150: 0 | M150: =K150-L150 | N150: =IF(ABS(L150)<1E-300,"",K150/L150) | O150: 1.7382113e+36 | P150: 0 | Q150: =O150-P150 | R150: =IF(ABS(P150)<1E-300,"",O150/P150) | S150: 0

Sheet Fig 5
A1: Figure 5: the static shell's metric along the y-axis with the Schwarzschild reference (r_s = 2GM/c^2 = 6.6667 m). Ours: the slice's g00 and g22 on the line; the Schwarzschild columns are the analytic -(1 - r_s/r) and 1/(1 - r_s/r), blank inside r_s.
A2: r [m] | B2: g00 shell: paper | C2: g00 shell: ours | D2: difference (paper - ours) | E2: ratio paper / ours | F2: g00 shell: replica at the figures' smoothing | G2: g22 shell: paper | H2: g22 shell: ours | I2: difference (paper - ours) | J2: ratio paper / ours | K2: g22 shell: replica at the figures' smoothing | L2: g00 Schwarzschild: paper | M2: g00 Schwarzschild: ours | N2: difference (paper - ours) | O2: ratio paper / ours | P2: g22 Schwarzschild: paper | Q2: g22 Schwarzschild: ours | R2: difference (paper - ours) | S2: ratio paper / ours
A3: 0.1 | B3: -0.5786463 | C3: -0.5802405 | D3: =B3-C3 | E3: =IF(ABS(C3)<1E-300,"",B3/C3) | F3: -0.57955847 | G3: 1.001197 | H3: 1 | I3: =G3-H3 | J3: =IF(ABS(H3)<1E-300,"",G3/H3) | K3: 1 | L3: -0.2490131 | M3: 65.666667 | N3: =L3-M3 | O3: =IF(ABS(M3)<1E-300,"",L3/M3) | R3: =P3-Q3 | S3: =IF(ABS(Q3)<1E-300,"",P3/Q3)
A4: 0.3 | B4: -0.5786463 | C4: -0.5802405 | D4: =B4-C4 | E4: =IF(ABS(C4)<1E-300,"",B4/C4) | F4: -0.57955847 | G4: 1.001197 | H4: 1 | I4: =G4-H4 | J4: =IF(ABS(H4)<1E-300,"",G4/H4) | K4: 1 | L4: -0.2490131 | M4: 21.222222 | N4: =L4-M4 | O4: =IF(ABS(M4)<1E-300,"",L4/M4) | R4: =P4-Q4 | S4: =IF(ABS(Q4)<1E-300,"",P4/Q4)
A5: 0.5 | B5: -0.5786463 | C5: -0.5802405 | D5: =B5-C5 | E5: =IF(ABS(C5)<1E-300,"",B5/C5) | F5: -0.57955847 | G5: 1.001197 | H5: 1 | I5: =G5-H5 | J5: =IF(ABS(H5)<1E-300,"",G5/H5) | K5: 1 | L5: -0.2490131 | M5: 12.333333 | N5: =L5-M5 | O5: =IF(ABS(M5)<1E-300,"",L5/M5) | R5: =P5-Q5 | S5: =IF(ABS(Q5)<1E-300,"",P5/Q5)
A6: 0.7 | B6: -0.5786463 | C6: -0.5802405 | D6: =B6-C6 | E6: =IF(ABS(C6)<1E-300,"",B6/C6) | F6: -0.57955847 | G6: 1.001197 | H6: 1 | I6: =G6-H6 | J6: =IF(ABS(H6)<1E-300,"",G6/H6) | K6: 1 | L6: -0.2490131 | M6: 8.5238095 | N6: =L6-M6 | O6: =IF(ABS(M6)<1E-300,"",L6/M6) | R6: =P6-Q6 | S6: =IF(ABS(Q6)<1E-300,"",P6/Q6)
A7: 0.9 | B7: -0.5786463 | C7: -0.5802405 | D7: =B7-C7 | E7: =IF(ABS(C7)<1E-300,"",B7/C7) | F7: -0.57955847 | G7: 1.001197 | H7: 1 | I7: =G7-H7 | J7: =IF(ABS(H7)<1E-300,"",G7/H7) | K7: 1 | L7: -0.2490131 | M7: 6.4074074 | N7: =L7-M7 | O7: =IF(ABS(M7)<1E-300,"",L7/M7) | R7: =P7-Q7 | S7: =IF(ABS(Q7)<1E-300,"",P7/Q7)
A8: 1.1 | B8: -0.5786463 | C8: -0.5802405 | D8: =B8-C8 | E8: =IF(ABS(C8)<1E-300,"",B8/C8) | F8: -0.57955847 | G8: 1.001197 | H8: 1 | I8: =G8-H8 | J8: =IF(ABS(H8)<1E-300,"",G8/H8) | K8: 1 | L8: -0.2490131 | M8: 5.0606061 | N8: =L8-M8 | O8: =IF(ABS(M8)<1E-300,"",L8/M8) | R8: =P8-Q8 | S8: =IF(ABS(Q8)<1E-300,"",P8/Q8)
A9: 1.3 | B9: -0.5786463 | C9: -0.5802405 | D9: =B9-C9 | E9: =IF(ABS(C9)<1E-300,"",B9/C9) | F9: -0.57955847 | G9: 1.001197 | H9: 1 | I9: =G9-H9 | J9: =IF(ABS(H9)<1E-300,"",G9/H9) | K9: 1 | L9: -0.2490131 | M9: 4.1282051 | N9: =L9-M9 | O9: =IF(ABS(M9)<1E-300,"",L9/M9) | R9: =P9-Q9 | S9: =IF(ABS(Q9)<1E-300,"",P9/Q9)
A10: 1.5 | B10: -0.5786463 | C10: -0.5802405 | D10: =B10-C10 | E10: =IF(ABS(C10)<1E-300,"",B10/C10) | F10: -0.57955847 | G10: 1.001197 | H10: 1 | I10: =G10-H10 | J10: =IF(ABS(H10)<1E-300,"",G10/H10) | K10: 1 | L10: -0.2490131 | M10: 3.4444444 | N10: =L10-M10 | O10: =IF(ABS(M10)<1E-300,"",L10/M10) | R10: =P10-Q10 | S10: =IF(ABS(Q10)<1E-300,"",P10/Q10)
A11: 1.7 | B11: -0.5786463 | C11: -0.5802405 | D11: =B11-C11 | E11: =IF(ABS(C11)<1E-300,"",B11/C11) | F11: -0.57955847 | G11: 1.001197 | H11: 1 | I11: =G11-H11 | J11: =IF(ABS(H11)<1E-300,"",G11/H11) | K11: 1 | L11: -0.2490131 | M11: 2.9215686 | N11: =L11-M11 | O11: =IF(ABS(M11)<1E-300,"",L11/M11) | R11: =P11-Q11 | S11: =IF(ABS(Q11)<1E-300,"",P11/Q11)
A12: 1.9 | B12: -0.5786463 | C12: -0.5802405 | D12: =B12-C12 | E12: =IF(ABS(C12)<1E-300,"",B12/C12) | F12: -0.57955847 | G12: 1.001197 | H12: 1 | I12: =G12-H12 | J12: =IF(ABS(H12)<1E-300,"",G12/H12) | K12: 1 | L12: -0.2490131 | M12: 2.5087719 | N12: =L12-M12 | O12: =IF(ABS(M12)<1E-300,"",L12/M12) | R12: =P12-Q12 | S12: =IF(ABS(Q12)<1E-300,"",P12/Q12)
A13: 2.1 | B13: -0.5786463 | C13: -0.5802405 | D13: =B13-C13 | E13: =IF(ABS(C13)<1E-300,"",B13/C13) | F13: -0.57955847 | G13: 1.001197 | H13: 1 | I13: =G13-H13 | J13: =IF(ABS(H13)<1E-300,"",G13/H13) | K13: 1 | L13: -0.2490131 | M13: 2.1746032 | N13: =L13-M13 | O13: =IF(ABS(M13)<1E-300,"",L13/M13) | R13: =P13-Q13 | S13: =IF(ABS(Q13)<1E-300,"",P13/Q13)
A14: 2.3 | B14: -0.5786463 | C14: -0.5802405 | D14: =B14-C14 | E14: =IF(ABS(C14)<1E-300,"",B14/C14) | F14: -0.57955847 | G14: 1.001197 | H14: 1 | I14: =G14-H14 | J14: =IF(ABS(H14)<1E-300,"",G14/H14) | K14: 1 | L14: -0.2490131 | M14: 1.8985507 | N14: =L14-M14 | O14: =IF(ABS(M14)<1E-300,"",L14/M14) | R14: =P14-Q14 | S14: =IF(ABS(Q14)<1E-300,"",P14/Q14)
... A35: 6.5 | B35: -0.5786545 | C35: -0.58027202 | D35: =B35-C35 | E35: =IF(ABS(C35)<1E-300,"",B35/C35) | F35: -0.57956684 | G35: 1.0013992 | H35: 1.0005544 | I35: =G35-H35 | J35: =IF(ABS(H35)<1E-300,"",G35/H35) | K35: 1.0002067 | L35: -0.2490131 | M35: 0.025641026 | N35: =L35-M35 | O35: =IF(ABS(M35)<1E-300,"",L35/M35) | R35: =P35-Q35 | S35: =IF(ABS(Q35)<1E-300,"",P35/Q35)
A36: 6.7 | B36: -0.57865882 | C36: -0.58028341 | D36: =B36-C36 | E36: =IF(ABS(C36)<1E-300,"",B36/C36) | F36: -0.57957127 | G36: 1.0014942 | H36: 1.0007372 | I36: =G36-H36 | J36: =IF(ABS(H36)<1E-300,"",G36/H36) | K36: 1.0003032 | L36: -0.2490131 | M36: -0.0049751244 | N36: =L36-M36 | O36: =IF(ABS(M36)<1E-300,"",L36/M36) | P36: 2.001316 | Q36: 201 | R36: =P36-Q36 | S36: =IF(ABS(Q36)<1E-300,"",P36/Q36)
A37: 6.9 | B37: -0.5786649 | C37: -0.58029816 | D37: =B37-C37 | E37: =IF(ABS(C37)<1E-300,"",B37/C37) | F37: -0.57957752 | G37: 1.0016233 | H37: 1.0009671 | I37: =G37-H37 | J37: =IF(ABS(H37)<1E-300,"",G37/H37) | K37: 1.000434 | L37: -0.2490131 | M37: -0.033816425 | N37: =L37-M37 | O37: =IF(ABS(M37)<1E-300,"",L37/M37) | P37: 2.001316 | Q37: 29.571429 | R37: =P37-Q37 | S37: =IF(ABS(Q37)<1E-300,"",P37/Q37)
A38: 7.1 | B38: -0.57867351 | C38: -0.58031715 | D38: =B38-C38 | E38: =IF(ABS(C38)<1E-300,"",B38/C38) | F38: -0.57958619 | G38: 1.0017951 | H38: 1.001253 | I38: =G38-H38 | J38: =IF(ABS(H38)<1E-300,"",G38/H38) | K38: 1.000608 | L38: -0.2490131 | M38: -0.061032864 | N38: =L38-M38 | O38: =IF(ABS(M38)<1E-300,"",L38/M38) | P38: 2.001316 | Q38: 16.384615 | R38: =P38-Q38 | S38: =IF(ABS(Q38)<1E-300,"",P38/Q38)
A39: 7.3 | B39: -0.57868522 | C39: -0.58034147 | D39: =B39-C39 | E39: =IF(ABS(C39)<1E-300,"",B39/C39) | F39: -0.57959809 | G39: 1.0020193 | H39: 1.0016047 | I39: =G39-H39 | J39: =IF(ABS(H39)<1E-300,"",G39/H39) | K39: 1.0008356 | L39: -0.2490131 | M39: -0.086757991 | N39: =L39-M39 | O39: =IF(ABS(M39)<1E-300,"",L39/M39) | P39: 2.001316 | Q39: 11.526316 | R39: =P39-Q39 | S39: =IF(ABS(Q39)<1E-300,"",P39/Q39)
A40: 7.5 | B40: -0.57870111 | C40: -0.58037244 | D40: =B40-C40 | E40: =IF(ABS(C40)<1E-300,"",B40/C40) | F40: -0.57961427 | G40: 1.0023092 | H40: 1.0020329 | I40: =G40-H40 | J40: =IF(ABS(H40)<1E-300,"",G40/H40) | K40: 1.0011289 | L40: -0.2490131 | M40: -0.11111111 | N40: =L40-M40 | O40: =IF(ABS(M40)<1E-300,"",L40/M40) | P40: 2.001316 | Q40: 9 | R40: =P40-Q40 | S40: =IF(ABS(Q40)<1E-300,"",P40/Q40)
A41: 7.7 | B41: -0.57872271 | C41: -0.58041167 | D41: =B41-C41 | E41: =IF(ABS(C41)<1E-300,"",B41/C41) | F41: -0.57963613 | G41: 1.0026772 | H41: 1.0025488 | I41: =G41-H41 | J41: =IF(ABS(H41)<1E-300,"",G41/H41) | K41: 1.0015013 | L41: -0.2490131 | M41: -0.13419913 | N41: =L41-M41 | O41: =IF(ABS(M41)<1E-300,"",L41/M41) | P41: 2.001316 | Q41: 7.4516129 | R41: =P41-Q41 | S41: =IF(ABS(Q41)<1E-300,"",P41/Q41)
A42: 7.9 | B42: -0.5787516 | C42: -0.58046109 | D42: =B42-C42 | E42: =IF(ABS(C42)<1E-300,"",B42/C42) | F42: -0.57966541 | G42: 1.003138 | H42: 1.0031645 | I42: =G42-H42 | J42: =IF(ABS(H42)<1E-300,"",G42/H42) | K42: 1.0019672 | L42: -0.2490131 | M42: -0.15611814 | N42: =L42-M42 | O42: =IF(ABS(M42)<1E-300,"",L42/M42) | P42: 2.001316 | Q42: 6.4054054 | R42: =P42-Q42 | S42: =IF(ABS(Q42)<1E-300,"",P42/Q42)
A43: 8.1 | B43: -0.57879 | C43: -0.58052299 | D43: =B43-C43 | E43: =IF(ABS(C43)<1E-300,"",B43/C43) | F43: -0.5797043 | G43: 1.003707 | H43: 1.0038925 | I43: =G43-H43 | J43: =IF(ABS(H43)<1E-300,"",G43/H43) | K43: 1.0025424 | L43: -0.2490131 | M43: -0.17695473 | N43: =L43-M43 | O43: =IF(ABS(M43)<1E-300,"",L43/M43) | P43: 2.001316 | Q43: 5.6511628 | R43: =P43-Q43 | S43: =IF(ABS(Q43)<1E-300,"",P43/Q43)
A44: 8.3 | B44: -0.57884057 | C44: -0.58060002 | D44: =B44-C44 | E44: =IF(ABS(C44)<1E-300,"",B44/C44) | F44: -0.57975546 | G44: 1.0044016 | H44: 1.0047459 | I44: =G44-H44 | J44: =IF(ABS(H44)<1E-300,"",G44/H44) | K44: 1.0032435 | L44: -0.2490131 | M44: -0.19678715 | N44: =L44-M44 | O44: =IF(ABS(M44)<1E-300,"",L44/M44) | P44: 2.001316 | Q44: 5.0816327 | R44: =P44-Q44 | S44: =IF(ABS(Q44)<1E-300,"",P44/Q44)
A45: 8.5 | B45: -0.57890637 | C45: -0.58069525 | D45: =B45-C45 | E45: =IF(ABS(C45)<1E-300,"",B45/C45) | F45: -0.57982211 | G45: 1.0052375 | H45: 1.0057381 | I45: =G45-H45 | J45: =IF(ABS(H45)<1E-300,"",G45/H45) | K45: 1.0040877 | L45: -0.2490131 | M45: -0.21568627 | N45: =L45-M45 | O45: =IF(ABS(M45)<1E-300,"",L45/M45) | P45: 2.001316 | Q45: 4.6363636 | R45: =P45-Q45 | S45: =IF(ABS(Q45)<1E-300,"",P45/Q45)
A46: 8.7 | B46: -0.57899131 | C46: -0.58081202 | D46: =B46-C46 | E46: =IF(ABS(C46)<1E-300,"",B46/C46) | F46: -0.57990802 | G46: 1.0062339 | H46: 1.0068826 | I46: =G46-H46 | J46: =IF(ABS(H46)<1E-300,"",G46/H46) | K46: 1.0050929 | L46: -0.2490131 | M46: -0.23371648 | N46: =L46-M46 | O46: =IF(ABS(M46)<1E-300,"",L46/M46) | P46: 2.001316 | Q46: 4.2786885 | R46: =P46-Q46 | S46: =IF(ABS(Q46)<1E-300,"",P46/Q46)
A47: 8.9 | B47: -0.57909948 | C47: -0.58095391 | D47: =B47-C47 | E47: =IF(ABS(C47)<1E-300,"",B47/C47) | F47: -0.58001737 | G47: 1.0074078 | H47: 1.0081933 | I47: =G47-H47 | J47: =IF(ABS(H47)<1E-300,"",G47/H47) | K47: 1.0062769 | L47: -0.2490131 | M47: -0.25093633 | N47: =L47-M47 | O47: =IF(ABS(M47)<1E-300,"",L47/M47) | P47: 2.001316 | Q47: 3.9850746 | R47: =P47-Q47 | S47: =IF(ABS(Q47)<1E-300,"",P47/Q47)
... A150: 29.5 | B150: -0.76990165 | C150: -0.76976081 | D150: =B150-C150 | E150: =IF(ABS(C150)<1E-300,"",B150/C150) | F150: -0.77092776 | G150: 1.2985512 | H150: 1.2991014 | I150: =G150-H150 | J150: =IF(ABS(H150)<1E-300,"",G150/H150) | K150: 1.2971384 | L150: -0.77073465 | M150: -0.7740113 | N150: =L150-M150 | O150: =IF(ABS(M150)<1E-300,"",L150/M150) | P150: 1.2971512 | Q150: 1.2919708 | R150: =P150-Q150 | S150: =IF(ABS(Q150)<1E-300,"",P150/Q150)

Sheet Fig 6
A1: Figure 6: the static shell's Eulerian stress-energy along the y-axis. On this axis P_2 = P_yy is the radial pressure and P_1 = P_xx = P_3 = P_zz the tangential one. Replica: smoothed inputs, radial pressure (= P~) and the tangential pressure from the equilibrium identity, at the fitted spans.
A2: r [m] | B2: energy density rho: paper | C2: energy density rho: ours | D2: difference (paper - ours) | E2: ratio paper / ours | F2: rho~ smoothed input (x c^2): paper | G2: rho~ smoothed input (x c^2): ours | H2: difference (paper - ours) | I2: ratio paper / ours | J2: rho~ smoothed input (x c^2): replica at the figures' smoothing | K2: P_2 radial: paper | L2: P_2 radial: ours | M2: difference (paper - ours) | N2: ratio paper / ours | O2: P_2 radial: replica at the figures' smoothing | P2: P_1 = P_3 tangential: paper | Q2: P_1 = P_3 tangential: ours | R2: difference (paper - ours) | S2: ratio paper / ours | T2: P_1 = P_3 tangential: replica at the figures' smoothing | U2: P~ smoothed input: paper | V2: P~ smoothed input: ours | W2: difference (paper - ours) | X2: ratio paper / ours | Y2: P~ smoothed input: replica at the figures' smoothing
A3: 0.1 | B3: 1.737989e+37 | C3: -4.4087816e+27 | D3: =B3-C3 | E3: =IF(ABS(C3)<1E-300,"",B3/C3) | F3: 1.737989e+37 | G3: 0 | H3: =F3-G3 | I3: =IF(ABS(G3)<1E-300,"",F3/G3) | J3: 0 | K3: 6.372753e+36 | L3: 2.459636e+27 | M3: =K3-L3 | N3: =IF(ABS(L3)<1E-300,"",K3/L3) | O3: 0 | P3: 6.372753e+36 | Q3: 2.9237183e+27 | R3: =P3-Q3 | S3: =IF(ABS(Q3)<1E-300,"",P3/Q3) | T3: 0 | U3: 6.372753e+36 | V3: 0 | W3: =U3-V3 | X3: =IF(ABS(V3)<1E-300,"",U3/V3) | Y3: 0
A4: 0.3 | B4: 1.737989e+37 | C4: -2.5988607e+27 | D4: =B4-C4 | E4: =IF(ABS(C4)<1E-300,"",B4/C4) | F4: 1.737989e+37 | G4: 0 | H4: =F4-G4 | I4: =IF(ABS(G4)<1E-300,"",F4/G4) | J4: 0 | K4: 6.372753e+36 | L4: -1.3922468e+26 | M4: =K4-L4 | N4: =IF(ABS(L4)<1E-300,"",K4/L4) | O4: 0 | P4: 6.372753e+36 | Q4: -2.2740031e+27 | R4: =P4-Q4 | S4: =IF(ABS(Q4)<1E-300,"",P4/Q4) | T4: 0 | U4: 6.372753e+36 | V4: 0 | W4: =U4-V4 | X4: =IF(ABS(V4)<1E-300,"",U4/V4) | Y4: 0
A5: 0.5 | B5: 1.737989e+37 | C5: 1.8099209e+27 | D5: =B5-C5 | E5: =IF(ABS(C5)<1E-300,"",B5/C5) | F5: 1.737989e+37 | G5: 0 | H5: =F5-G5 | I5: =IF(ABS(G5)<1E-300,"",F5/G5) | J5: 0 | K5: 6.372753e+36 | L5: 3.2893899e+28 | M5: =K5-L5 | N5: =IF(ABS(L5)<1E-300,"",K5/L5) | O5: 0 | P5: 6.3726511e+36 | Q5: 2.5190133e+28 | R5: =P5-Q5 | S5: =IF(ABS(Q5)<1E-300,"",P5/Q5) | T5: 0 | U5: 6.372753e+36 | V5: 0 | W5: =U5-V5 | X5: =IF(ABS(V5)<1E-300,"",U5/V5) | Y5: 0
A6: 0.7 | B6: 1.737989e+37 | C6: -6.9612341e+28 | D6: =B6-C6 | E6: =IF(ABS(C6)<1E-300,"",B6/C6) | F6: 1.737989e+37 | G6: 0 | H6: =F6-G6 | I6: =IF(ABS(G6)<1E-300,"",F6/G6) | J6: 0 | K6: 6.3709197e+36 | L6: 2.9598915e+28 | M6: =K6-L6 | N6: =IF(ABS(L6)<1E-300,"",K6/L6) | O6: 0 | P6: 6.372753e+36 | Q6: 1.3488965e+29 | R6: =P6-Q6 | S6: =IF(ABS(Q6)<1E-300,"",P6/Q6) | T6: 0 | U6: 6.372753e+36 | V6: 0 | W6: =U6-V6 | X6: =IF(ABS(V6)<1E-300,"",U6/V6) | Y6: 0
A7: 0.9 | B7: 1.737989e+37 | C7: -5.8242325e+27 | D7: =B7-C7 | E7: =IF(ABS(C7)<1E-300,"",B7/C7) | F7: 1.737989e+37 | G7: 0 | H7: =F7-G7 | I7: =IF(ABS(G7)<1E-300,"",F7/G7) | J7: 0 | K7: 6.3709197e+36 | L7: 1.8563291e+26 | M7: =K7-L7 | N7: =IF(ABS(L7)<1E-300,"",K7/L7) | O7: 0 | P7: 6.3709197e+36 | Q7: -2.9608449e+28 | R7: =P7-Q7 | S7: =IF(ABS(Q7)<1E-300,"",P7/Q7) | T7: 0 | U7: 6.372753e+36 | V7: 0 | W7: =U7-V7 | X7: =IF(ABS(V7)<1E-300,"",U7/V7) | Y7: 0
A8: 1.1 | B8: 1.737989e+37 | C8: -3.1731625e+28 | D8: =B8-C8 | E8: =IF(ABS(C8)<1E-300,"",B8/C8) | F8: 1.737989e+37 | G8: 0 | H8: =F8-G8 | I8: =IF(ABS(G8)<1E-300,"",F8/G8) | J8: 0 | K8: 6.3710215e+36 | L8: -2.4364319e+26 | M8: =K8-L8 | N8: =IF(ABS(L8)<1E-300,"",K8/L8) | O8: 0 | P8: 6.372753e+36 | Q8: 1.4572183e+28 | R8: =P8-Q8 | S8: =IF(ABS(Q8)<1E-300,"",P8/Q8) | T8: 0 | U8: 6.372753e+36 | V8: 0 | W8: =U8-V8 | X8: =IF(ABS(V8)<1E-300,"",U8/V8) | Y8: 0
A9: 1.3 | B9: 1.737989e+37 | C9: -3.5177436e+28 | D9: =B9-C9 | E9: =IF(ABS(C9)<1E-300,"",B9/C9) | F9: 1.737989e+37 | G9: 0 | H9: =F9-G9 | I9: =IF(ABS(G9)<1E-300,"",F9/G9) | J9: 0 | K9: 6.3710215e+36 | L9: 9.2816454e+25 | M9: =K9-L9 | N9: =IF(ABS(L9)<1E-300,"",K9/L9) | O9: 0 | P9: 6.3710215e+36 | Q9: 3.2114493e+28 | R9: =P9-Q9 | S9: =IF(ABS(Q9)<1E-300,"",P9/Q9) | T9: 0 | U9: 6.372753e+36 | V9: 0 | W9: =U9-V9 | X9: =IF(ABS(V9)<1E-300,"",U9/V9) | Y9: 0
A10: 1.5 | B10: 1.737989e+37 | C10: -3.3947618e+28 | D10: =B10-C10 | E10: =IF(ABS(C10)<1E-300,"",B10/C10) | F10: 1.737989e+37 | G10: 0 | H10: =F10-G10 | I10: =IF(ABS(G10)<1E-300,"",F10/G10) | J10: 0 | K10: 6.3731604e+36 | L10: -3.2485759e+26 | M10: =K10-L10 | N10: =IF(ABS(L10)<1E-300,"",K10/L10) | O10: 0 | P10: 6.372753e+36 | Q10: 7.27681e+28 | R10: =P10-Q10 | S10: =IF(ABS(Q10)<1E-300,"",P10/Q10) | T10: 0 | U10: 6.372753e+36 | V10: 0 | W10: =U10-V10 | X10: =IF(ABS(V10)<1E-300,"",U10/V10) | Y10: 0
A11: 1.7 | B11: 1.737989e+37 | C11: -2.0651661e+27 | D11: =B11-C11 | E11: =IF(ABS(C11)<1E-300,"",B11/C11) | F11: 1.737989e+37 | G11: 0 | H11: =F11-G11 | I11: =IF(ABS(G11)<1E-300,"",F11/G11) | J11: 0 | K11: 6.372753e+36 | L11: -3.0619896e+28 | M11: =K11-L11 | N11: =IF(ABS(L11)<1E-300,"",K11/L11) | O11: 0 | P11: 6.372753e+36 | Q11: -2.7000054e+28 | R11: =P11-Q11 | S11: =IF(ABS(Q11)<1E-300,"",P11/Q11) | T11: 0 | U11: 6.372753e+36 | V11: 0 | W11: =U11-V11 | X11: =IF(ABS(V11)<1E-300,"",U11/V11) | Y11: 0
A12: 1.9 | B12: 1.737989e+37 | C12: -3.5015007e+28 | D12: =B12-C12 | E12: =IF(ABS(C12)<1E-300,"",B12/C12) | F12: 1.737989e+37 | G12: 0 | H12: =F12-G12 | I12: =IF(ABS(G12)<1E-300,"",F12/G12) | J12: 0 | K12: 6.372753e+36 | L12: 3.480617e+26 | M12: =K12-L12 | N12: =IF(ABS(L12)<1E-300,"",K12/L12) | O12: 0 | P12: 6.3712253e+36 | Q12: 1.6057247e+28 | R12: =P12-Q12 | S12: =IF(ABS(Q12)<1E-300,"",P12/Q12) | T12: 0 | U12: 6.372753e+36 | V12: 0 | W12: =U12-V12 | X12: =IF(ABS(V12)<1E-300,"",U12/V12) | Y12: 0
A13: 2.1 | B13: 1.737989e+37 | C13: 2.1811867e+27 | D13: =B13-C13 | E13: =IF(ABS(C13)<1E-300,"",B13/C13) | F13: 1.737989e+37 | G13: 0 | H13: =F13-G13 | I13: =IF(ABS(G13)<1E-300,"",F13/G13) | J13: 0 | K13: 6.372753e+36 | L13: 3.480617e+26 | M13: =K13-L13 | N13: =IF(ABS(L13)<1E-300,"",K13/L13) | O13: 0 | P13: 6.372753e+36 | Q13: -1.2994304e+27 | R13: =P13-Q13 | S13: =IF(ABS(Q13)<1E-300,"",P13/Q13) | T13: 0 | U13: 6.372753e+36 | V13: 0 | W13: =U13-V13 | X13: =IF(ABS(V13)<1E-300,"",U13/V13) | Y13: 0
A14: 2.3 | B14: 1.737989e+37 | C14: -7.0111229e+28 | D14: =B14-C14 | E14: =IF(ABS(C14)<1E-300,"",B14/C14) | F14: 1.737989e+37 | G14: 0 | H14: =F14-G14 | I14: =IF(ABS(G14)<1E-300,"",F14/G14) | J14: 0 | K14: 6.372753e+36 | L14: -4.292761e+26 | M14: =K14-L14 | N14: =IF(ABS(L14)<1E-300,"",K14/L14) | O14: 0 | P14: 6.372753e+36 | Q14: 7.1329445e+28 | R14: =P14-Q14 | S14: =IF(ABS(Q14)<1E-300,"",P14/Q14) | T14: 0 | U14: 6.372753e+36 | V14: 0 | W14: =U14-V14 | X14: =IF(ABS(V14)<1E-300,"",U14/V14) | Y14: 0
... A150: 29.5 | B150: 1.737989e+37 | C150: 4.6290447e+32 | D150: =B150-C150 | E150: =IF(ABS(C150)<1E-300,"",B150/C150) | F150: 1.737989e+37 | G150: 0 | H150: =F150-G150 | I150: =IF(ABS(G150)<1E-300,"",F150/G150) | J150: 0 | K150: 6.372753e+36 | L150: 4.9976492e+31 | M150: =K150-L150 | N150: =IF(ABS(L150)<1E-300,"",K150/L150) | O150: 0 | P150: 6.372753e+36 | Q150: -2.4584931e+32 | R150: =P150-Q150 | S150: =IF(ABS(Q150)<1E-300,"",P150/Q150) | T150: 0 | U150: 6.372753e+36 | V150: 0 | W150: =U150-V150 | X150: =IF(ABS(V150)<1E-300,"",U150/V150) | Y150: 0

Sheet Fig 7
A1: Figure 7: the static shell's four sampled energy-condition maps (WarpFactory, 100 directions x 10 speeds), the paper's method. The exported Null and Weak maps lower indices with the coordinate metric (claim C9); 'consistent metric' columns are the same observer set evaluated with Minkowski, ours only.
A2: r [m] | B2: Null: paper | C2: Null: ours | D2: difference (paper - ours) | E2: ratio paper / ours | F2: Weak: paper | G2: Weak: ours | H2: difference (paper - ours) | I2: ratio paper / ours | J2: Strong: paper | K2: Strong: ours | L2: difference (paper - ours) | M2: ratio paper / ours | N2: Dominant: paper | O2: Dominant: ours | P2: difference (paper - ours) | Q2: ratio paper / ours | R2: Null, consistent metric: paper | S2: Null, consistent metric: ours | T2: difference (paper - ours) | U2: ratio paper / ours | V2: Weak, consistent metric: paper | W2: Weak, consistent metric: ours | X2: difference (paper - ours) | Y2: ratio paper / ours
A3: 0.1 | B3: 1.971376e+37 | C3: -5.4203548e+27 | D3: =B3-C3 | E3: =IF(ABS(C3)<1E-300,"",B3/C3) | F3: 1.971376e+37 | G3: -5.4203548e+27 | H3: =F3-G3 | I3: =IF(ABS(G3)<1E-300,"",F3/G3) | J3: 1.979729e+37 | K3: -6.8825734e+27 | L3: =J3-K3 | M3: =IF(ABS(K3)<1E-300,"",J3/K3) | N3: 1.979729e+37 | O3: -1.0059317e+28 | P3: =N3-O3 | Q3: =IF(ABS(O3)<1E-300,"",N3/O3) | S3: -6.8825734e+27 | W3: -6.8825734e+27
A4: 0.3 | B4: 1.971376e+37 | C4: -3.0506478e+27 | D4: =B4-C4 | E4: =IF(ABS(C4)<1E-300,"",B4/C4) | F4: 1.971376e+37 | G4: -3.0506478e+27 | H4: =F4-G4 | I4: =IF(ABS(G4)<1E-300,"",F4/G4) | J4: 1.979729e+37 | K4: -3.9125872e+27 | L4: =J4-K4 | M4: =IF(ABS(K4)<1E-300,"",J4/K4) | N4: 1.979729e+37 | O4: -5.4117077e+27 | P4: =N4-O4 | Q4: =IF(ABS(O4)<1E-300,"",N4/O4) | S4: -3.9125872e+27 | W4: -3.9125872e+27
A5: 0.5 | B5: 1.971376e+37 | C5: -1.2417808e+26 | D5: =B5-C5 | E5: =IF(ABS(C5)<1E-300,"",B5/C5) | F5: 1.971376e+37 | G5: -1.2417808e+26 | H5: =F5-G5 | I5: =IF(ABS(G5)<1E-300,"",F5/G5) | J5: 1.979729e+37 | K5: 4.7610115e+26 | L5: =J5-K5 | M5: =IF(ABS(K5)<1E-300,"",J5/K5) | N5: 1.979729e+37 | O5: -3.0209847e+28 | P5: =N5-O5 | Q5: =IF(ABS(O5)<1E-300,"",N5/O5) | S5: 4.7610115e+26 | W5: 4.7610115e+26
A6: 0.7 | B6: 1.971376e+37 | C6: 1.4844016e+27 | D6: =B6-C6 | E6: =IF(ABS(C6)<1E-300,"",B6/C6) | F6: 1.971376e+37 | G6: -2.3437016e+28 | H6: =F6-G6 | I6: =IF(ABS(G6)<1E-300,"",F6/G6) | J6: 1.979729e+37 | K6: -2.1603261e+28 | L6: =J6-K6 | M6: =IF(ABS(K6)<1E-300,"",J6/K6) | N6: 1.979729e+37 | O6: -8.3216478e+28 | P6: =N6-O6 | Q6: =IF(ABS(O6)<1E-300,"",N6/O6) | S6: -2.1603261e+28 | W6: -6.9612341e+28
A7: 0.9 | B7: 1.971376e+37 | C7: -1.6186661e+28 | D7: =B7-C7 | E7: =IF(ABS(C7)<1E-300,"",B7/C7) | F7: 1.971376e+37 | G7: -1.6186661e+28 | H7: =F7-G7 | I7: =IF(ABS(G7)<1E-300,"",F7/G7) | J7: 1.979729e+37 | K7: -1.8118329e+28 | L7: =J7-K7 | M7: =IF(ABS(K7)<1E-300,"",J7/K7) | N7: 1.979729e+37 | O7: -2.5482783e+28 | P7: =N7-O7 | Q7: =IF(ABS(O7)<1E-300,"",N7/O7) | S7: -1.8118329e+28 | W7: -1.8118329e+28
A8: 1.1 | B8: 1.971376e+37 | C8: -5.8852673e+27 | D8: =B8-C8 | E8: =IF(ABS(C8)<1E-300,"",B8/C8) | F8: 1.971376e+37 | G8: -1.0683373e+28 | H8: =F8-G8 | I8: =IF(ABS(G8)<1E-300,"",F8/G8) | J8: 1.979729e+37 | K8: -1.6409394e+28 | L8: =J8-K8 | M8: =IF(ABS(K8)<1E-300,"",J8/K8) | N8: 1.979729e+37 | O8: 1.8453041e+28 | P8: =N8-O8 | Q8: =IF(ABS(O8)<1E-300,"",N8/O8) | S8: -1.6409394e+28 | W8: -3.1731625e+28
A9: 1.3 | B9: 1.971376e+37 | C9: -6.0625304e+27 | D9: =B9-C9 | E9: =IF(ABS(C9)<1E-300,"",B9/C9) | F9: 1.971376e+37 | G9: -1.1843505e+28 | H9: =F9-G9 | I9: =IF(ABS(G9)<1E-300,"",F9/G9) | J9: 1.979729e+37 | K9: -1.7729496e+28 | L9: =J9-K9 | M9: =IF(ABS(K9)<1E-300,"",J9/K9) | N9: 1.979729e+37 | O9: 9.1703624e+27 | P9: =N9-O9 | Q9: =IF(ABS(O9)<1E-300,"",N9/O9) | S9: -1.7729496e+28 | W9: -3.5177436e+28
A10: 1.5 | B10: 1.971376e+37 | C10: -2.5470908e+28 | D10: =B10-C10 | E10: =IF(ABS(C10)<1E-300,"",B10/C10) | F10: 1.971376e+37 | G10: -2.5470908e+28 | H10: =F10-G10 | I10: =IF(ABS(G10)<1E-300,"",F10/G10) | J10: 1.979729e+37 | K10: -3.6729991e+28 | L10: =J10-K10 | M10: =IF(ABS(K10)<1E-300,"",J10/K10) | N10: 1.979729e+37 | O10: -4.6325034e+28 | P10: =N10-O10 | Q10: =IF(ABS(O10)<1E-300,"",N10/O10) | S10: -3.6729991e+28 | W10: -3.6729991e+28
A11: 1.7 | B11: 1.971376e+37 | C11: -3.289539e+28 | D11: =B11-C11 | E11: =IF(ABS(C11)<1E-300,"",B11/C11) | F11: 1.971376e+37 | G11: -3.289539e+28 | H11: =F11-G11 | I11: =IF(ABS(G11)<1E-300,"",F11/G11) | J11: 1.979729e+37 | K11: -6.1425424e+28 | L11: =J11-K11 | M11: =IF(ABS(K11)<1E-300,"",J11/K11) | N11: 1.979729e+37 | O11: -4.6027299e+28 | P11: =N11-O11 | Q11: =IF(ABS(O11)<1E-300,"",N11/O11) | S11: -3.3580324e+28 | W11: -3.3580324e+28
A12: 1.9 | B12: 1.971376e+37 | C12: -8.7631604e+27 | D12: =B12-C12 | E12: =IF(ABS(C12)<1E-300,"",B12/C12) | F12: 1.971376e+37 | G12: -1.1788819e+28 | H12: =F12-G12 | I12: =IF(ABS(G12)<1E-300,"",F12/G12) | J12: 1.979729e+37 | K12: -2.0376255e+28 | L12: =J12-K12 | M12: =IF(ABS(K12)<1E-300,"",J12/K12) | N12: 1.979729e+37 | O12: 1.7931303e+28 | P12: =N12-O12 | Q12: =IF(ABS(O12)<1E-300,"",N12/O12) | S12: -2.0376255e+28 | W12: -3.5015007e+28
A13: 2.1 | B13: 1.971376e+37 | C13: -3.0069217e+27 | D13: =B13-C13 | E13: =IF(ABS(C13)<1E-300,"",B13/C13) | F13: 1.971376e+37 | G13: -3.0069217e+27 | H13: =F13-G13 | I13: =IF(ABS(G13)<1E-300,"",F13/G13) | J13: 1.979729e+37 | K13: -2.2835083e+27 | L13: =J13-K13 | M13: =IF(ABS(K13)<1E-300,"",J13/K13) | N13: 1.979729e+37 | O13: -4.5382234e+27 | P13: =N13-O13 | Q13: =IF(ABS(O13)<1E-300,"",N13/O13) | S13: -2.2835083e+27 | W13: -2.2835083e+27
A14: 2.3 | B14: 1.971376e+37 | C14: -1.2172269e+28 | D14: =B14-C14 | E14: =IF(ABS(C14)<1E-300,"",B14/C14) | F14: 1.971376e+37 | G14: -2.3604981e+28 | H14: =F14-G14 | I14: =IF(ABS(G14)<1E-300,"",F14/G14) | J14: 1.979729e+37 | K14: -3.5425393e+28 | L14: =J14-K14 | M14: =IF(ABS(K14)<1E-300,"",J14/K14) | N14: 1.979729e+37 | O14: -7.2569254e+27 | P14: =N14-O14 | Q14: =IF(ABS(O14)<1E-300,"",N14/O14) | S14: -3.5425393e+28 | W14: -7.0111229e+28
... A150: 29.5 | B150: 1.971376e+37 | C150: 1.4246597e+31 | D150: =B150-C150 | E150: =IF(ABS(C150)<1E-300,"",B150/C150) | F150: 1.971376e+37 | G150: 1.4246597e+31 | H150: =F150-G150 | I150: =IF(ABS(G150)<1E-300,"",F150/G150) | J150: 1.979729e+37 | K150: 1.0644445e+31 | L150: =J150-K150 | M150: =IF(ABS(K150)<1E-300,"",J150/K150) | N150: 1.979729e+37 | O150: 2.7735838e+32 | P150: =N150-O150 | Q150: =IF(ABS(O150)<1E-300,"",N150/O150) | S150: 1.0855475e+32 | W150: 1.0855475e+32

Sheet Fig 8
A1: Figure 8: the warp shell's metric along the y-axis (shift 0.02 along +x). The paper's Figure 8 is a raster image in the PDF, so there is no digitised paper column; the comparison is by eye in pairs/fig08_pair.png. Ours only.
A2: r [m] | B2: g00: paper | C2: g00: ours | D2: difference (paper - ours) | E2: ratio paper / ours | F2: g01: paper | G2: g01: ours | H2: difference (paper - ours) | I2: ratio paper / ours | J2: g22: paper | K2: g22: ours | L2: difference (paper - ours) | M2: ratio paper / ours
A3: 0.1 | C3: -0.5802405 | G3: -0.02 | K3: 1
A4: 0.3 | C4: -0.5802405 | G4: -0.02 | K4: 1
A5: 0.5 | C5: -0.5802405 | G5: -0.02 | K5: 1
A6: 0.7 | C6: -0.5802405 | G6: -0.02 | K6: 1
A7: 0.9 | C7: -0.5802405 | G7: -0.02 | K7: 1
A8: 1.1 | C8: -0.5802405 | G8: -0.02 | K8: 1
A9: 1.3 | C9: -0.5802405 | G9: -0.02 | K9: 1
A10: 1.5 | C10: -0.5802405 | G10: -0.02 | K10: 1
A11: 1.7 | C11: -0.5802405 | G11: -0.02 | K11: 1
A12: 1.9 | C12: -0.5802405 | G12: -0.02 | K12: 1
A13: 2.1 | C13: -0.5802405 | G13: -0.02 | K13: 1
A14: 2.3 | C14: -0.5802405 | G14: -0.02 | K14: 1
... A150: 29.5 | C150: -0.76976081 | G150: 0 | K150: 1.2991014

Sheet Fig 9
A1: Figure 9: the warp shell's Eulerian stress-energy along the y-axis (shift 0.02 along +x). p_1 = p_x is the momentum density; sigma_12 = P_xy is the shear, which vanishes on the exact axis and is 1.9e37 at our line's x = -0.1 m.
A2: r [m] | B2: energy density rho: paper | C2: energy density rho: ours | D2: difference (paper - ours) | E2: ratio paper / ours | F2: P_2 radial: paper | G2: P_2 radial: ours | H2: difference (paper - ours) | I2: ratio paper / ours | J2: P_1: paper | K2: P_1: ours | L2: difference (paper - ours) | M2: ratio paper / ours | N2: P_3: paper | O2: P_3: ours | P2: difference (paper - ours) | Q2: ratio paper / ours | R2: momentum p_1 (x c): paper | S2: momentum p_1 (x c): ours | T2: difference (paper - ours) | U2: ratio paper / ours | V2: momentum p_2 = p_3 (x c): paper | W2: momentum p_2 = p_3 (x c): ours | X2: difference (paper - ours) | Y2: ratio paper / ours | Z2: shear sigma_12: paper | AA2: shear sigma_12: ours | AB2: difference (paper - ours) | AC2: ratio paper / ours
A3: 0.1 | B3: 1.848195e+37 | C3: -4.4087816e+27 | D3: =B3-C3 | E3: =IF(ABS(C3)<1E-300,"",B3/C3) | F3: 6.776426e+36 | G3: 2.4579416e+27 | H3: =F3-G3 | I3: =IF(ABS(G3)<1E-300,"",F3/G3) | J3: 6.776426e+36 | K3: 2.9226953e+27 | L3: =J3-K3 | M3: =IF(ABS(K3)<1E-300,"",J3/K3) | N3: 6.776426e+36 | O3: -9.7390139e+26 | P3: =N3-O3 | Q3: =IF(ABS(O3)<1E-300,"",N3/O3) | R3: 1.979361e+37 | S3: 3.8978156e+25 | T3: =R3-S3 | U3: =IF(ABS(S3)<1E-300,"",R3/S3) | V3: 1.979361e+37 | W3: 1.1784802e+26 | X3: =V3-W3 | Y3: =IF(ABS(W3)<1E-300,"",V3/W3) | Z3: 4.948534e+35 | AA3: -1.2188402e+28 | AB3: =Z3-AA3 | AC3: =IF(ABS(AA3)<1E-300,"",Z3/AA3)
A4: 0.3 | B4: 1.848195e+37 | C4: -2.5988607e+27 | D4: =B4-C4 | E4: =IF(ABS(C4)<1E-300,"",B4/C4) | F4: 6.777509e+36 | G4: -1.3912877e+26 | H4: =F4-G4 | I4: =IF(ABS(G4)<1E-300,"",F4/G4) | J4: 6.7764801e+36 | K4: -2.27736e+27 | L4: =J4-K4 | M4: =IF(ABS(K4)<1E-300,"",J4/K4) | N4: 6.7764801e+36 | O4: 5.0086357e+27 | P4: =N4-O4 | Q4: =IF(ABS(O4)<1E-300,"",N4/O4) | R4: 1.979361e+37 | S4: 1.2789708e+26 | T4: =R4-S4 | U4: =IF(ABS(S4)<1E-300,"",R4/S4) | V4: 1.979361e+37 | W4: 2.0493984e+26 | X4: =V4-W4 | Y4: =IF(ABS(W4)<1E-300,"",V4/W4) | Z4: 4.948534e+35 | AA4: -2.5706336e+27 | AB4: =Z4-AA4 | AC4: =IF(ABS(AA4)<1E-300,"",Z4/AA4)
A5: 0.5 | B5: 1.848195e+37 | C5: 1.8099209e+27 | D5: =B5-C5 | E5: =IF(ABS(C5)<1E-300,"",B5/C5) | F5: 6.7774548e+36 | G5: 3.2871238e+28 | H5: =F5-G5 | I5: =IF(ABS(G5)<1E-300,"",F5/G5) | J5: 6.7774007e+36 | K5: 2.5166418e+28 | L5: =J5-K5 | M5: =IF(ABS(K5)<1E-300,"",J5/K5) | N5: 6.7774007e+36 | O5: 1.5304165e+27 | P5: =N5-O5 | Q5: =IF(ABS(O5)<1E-300,"",N5/O5) | R5: 1.979361e+37 | S5: 9.7445391e+25 | T5: =R5-S5 | U5: =IF(ABS(S5)<1E-300,"",R5/S5) | V5: 1.979361e+37 | W5: 4.4040749e+26 | X5: =V5-W5 | Y5: =IF(ABS(W5)<1E-300,"",V5/W5) | Z5: 4.948534e+35 | AA5: 1.1886227e+28 | AB5: =Z5-AA5 | AC5: =IF(ABS(AA5)<1E-300,"",Z5/AA5)
A6: 0.7 | B6: 1.848195e+37 | C6: -6.9612341e+28 | D6: =B6-C6 | E6: =IF(ABS(C6)<1E-300,"",B6/C6) | F6: 6.776426e+36 | G6: 2.9655253e+28 | H6: =F6-G6 | I6: =IF(ABS(G6)<1E-300,"",F6/G6) | J6: 6.7765343e+36 | K6: 1.3550218e+29 | L6: =J6-K6 | M6: =IF(ABS(K6)<1E-300,"",J6/K6) | N6: 6.7765343e+36 | O6: 2.8530822e+28 | P6: =N6-O6 | Q6: =IF(ABS(O6)<1E-300,"",N6/O6) | R6: 1.979361e+37 | S6: -1.2525387e+28 | T6: =R6-S6 | U6: =IF(ABS(S6)<1E-300,"",R6/S6) | V6: 1.979361e+37 | W6: -6.5557909e+27 | X6: =V6-W6 | Y6: =IF(ABS(W6)<1E-300,"",V6/W6) | Z6: 4.948534e+35 | AA6: 1.3980599e+28 | AB6: =Z6-AA6 | AC6: =IF(ABS(AA6)<1E-300,"",Z6/AA6)
A7: 0.9 | B7: 1.848195e+37 | C7: -5.8242325e+27 | D7: =B7-C7 | E7: =IF(ABS(C7)<1E-300,"",B7/C7) | F7: 6.776426e+36 | G7: 1.4714058e+26 | H7: =F7-G7 | I7: =IF(ABS(G7)<1E-300,"",F7/G7) | J7: 6.7755596e+36 | K7: -3.742084e+28 | L7: =J7-K7 | M7: =IF(ABS(K7)<1E-300,"",J7/K7) | N7: 6.7755596e+36 | O7: 2.747315e+28 | P7: =N7-O7 | Q7: =IF(ABS(O7)<1E-300,"",N7/O7) | R7: 1.979361e+37 | S7: 1.492906e+29 | T7: =R7-S7 | U7: =IF(ABS(S7)<1E-300,"",R7/S7) | V7: 1.979361e+37 | W7: 2.0356951e+27 | X7: =V7-W7 | Y7: =IF(ABS(W7)<1E-300,"",V7/W7) | Z7: 4.948534e+35 | AA7: -2.9431831e+27 | AB7: =Z7-AA7 | AC7: =IF(ABS(AA7)<1E-300,"",Z7/AA7)
A8: 1.1 | B8: 1.848195e+37 | C8: -3.1731625e+28 | D8: =B8-C8 | E8: =IF(ABS(C8)<1E-300,"",B8/C8) | F8: 6.776426e+36 | G8: -5.5039089e+26 | H8: =F8-G8 | I8: =IF(ABS(G8)<1E-300,"",F8/G8) | J8: 6.7765884e+36 | K8: 2.0008113e+28 | L8: =J8-K8 | M8: =IF(ABS(K8)<1E-300,"",J8/K8) | N8: 6.7765884e+36 | O8: 2.3145763e+28 | P8: =N8-O8 | Q8: =IF(ABS(O8)<1E-300,"",N8/O8) | R8: 1.979361e+37 | S8: -1.0332896e+29 | T8: =R8-S8 | U8: =IF(ABS(S8)<1E-300,"",R8/S8) | V8: 1.979361e+37 | W8: 7.330596e+27 | X8: =V8-W8 | Y8: =IF(ABS(W8)<1E-300,"",V8/W8) | Z8: 4.948534e+35 | AA8: -3.8412313e+27 | AB8: =Z8-AA8 | AC8: =IF(ABS(AA8)<1E-300,"",Z8/AA8)
A9: 1.3 | B9: 1.848195e+37 | C9: -3.5177436e+28 | D9: =B9-C9 | E9: =IF(ABS(C9)<1E-300,"",B9/C9) | F9: 6.7765884e+36 | G9: -1.7579859e+26 | H9: =F9-G9 | I9: =IF(ABS(G9)<1E-300,"",F9/G9) | J9: 6.7756679e+36 | K9: 3.1268365e+28 | L9: =J9-K9 | M9: =IF(ABS(K9)<1E-300,"",J9/K9) | N9: 6.7756679e+36 | O9: 2.3926138e+27 | P9: =N9-O9 | Q9: =IF(ABS(O9)<1E-300,"",N9/O9) | R9: 1.979361e+37 | S9: 1.6158882e+28 | T9: =R9-S9 | U9: =IF(ABS(S9)<1E-300,"",R9/S9) | V9: 1.979361e+37 | W9: -1.4884022e+27 | X9: =V9-W9 | Y9: =IF(ABS(W9)<1E-300,"",V9/W9) | Z9: 4.948534e+35 | AA9: 4.3514622e+27 | AB9: =Z9-AA9 | AC9: =IF(ABS(AA9)<1E-300,"",Z9/AA9)
A10: 1.5 | B10: 1.848195e+37 | C10: -3.3947618e+28 | D10: =B10-C10 | E10: =IF(ABS(C10)<1E-300,"",B10/C10) | F10: 6.7766426e+36 | G10: -6.3154934e+26 | H10: =F10-G10 | I10: =IF(ABS(G10)<1E-300,"",F10/G10) | J10: 6.7766426e+36 | K10: 7.4444515e+28 | L10: =J10-K10 | M10: =IF(ABS(K10)<1E-300,"",J10/K10) | N10: 6.7766426e+36 | O10: -3.6512518e+28 | P10: =N10-O10 | Q10: =IF(ABS(O10)<1E-300,"",N10/O10) | R10: 1.979361e+37 | S10: -3.2445052e+28 | T10: =R10-S10 | U10: =IF(ABS(S10)<1E-300,"",R10/S10) | V10: 1.979361e+37 | W10: -1.7309499e+27 | X10: =V10-W10 | Y10: =IF(ABS(W10)<1E-300,"",V10/W10) | Z10: 4.948534e+35 | AA10: 2.1313193e+27 | AB10: =Z10-AA10 | AC10: =IF(ABS(AA10)<1E-300,"",Z10/AA10)
A11: 1.7 | B11: 1.848195e+37 | C11: -2.0651661e+27 | D11: =B11-C11 | E11: =IF(ABS(C11)<1E-300,"",B11/C11) | F11: 6.776426e+36 | G11: -3.0637166e+28 | H11: =F11-G11 | I11: =IF(ABS(G11)<1E-300,"",F11/G11) | J11: 6.776426e+36 | K11: -2.7323041e+28 | L11: =J11-K11 | M11: =IF(ABS(K11)<1E-300,"",J11/K11) | N11: 6.776426e+36 | O11: -6.3429134e+28 | P11: =N11-O11 | Q11: =IF(ABS(O11)<1E-300,"",N11/O11) | R11: 1.979361e+37 | S11: 6.5343225e+27 | T11: =R11-S11 | U11: =IF(ABS(S11)<1E-300,"",R11/S11) | V11: 1.979361e+37 | W11: -7.2733849e+26 | X11: =V11-W11 | Y11: =IF(ABS(W11)<1E-300,"",V11/W11) | Z11: 4.948534e+35 | AA11: -2.3478326e+27 | AB11: =Z11-AA11 | AC11: =IF(ABS(AA11)<1E-300,"",Z11/AA11)
A12: 1.9 | B12: 1.848195e+37 | C12: -3.5015007e+28 | D12: =B12-C12 | E12: =IF(ABS(C12)<1E-300,"",B12/C12) | F12: 6.776426e+36 | G12: 2.7109304e+26 | H12: =F12-G12 | I12: =IF(ABS(G12)<1E-300,"",F12/G12) | J12: 6.7756138e+36 | K12: 1.5852365e+28 | L12: =J12-K12 | M12: =IF(ABS(K12)<1E-300,"",J12/K12) | N12: 6.7756138e+36 | O12: 1.8481786e+28 | P12: =N12-O12 | Q12: =IF(ABS(O12)<1E-300,"",N12/O12) | R12: 1.979361e+37 | S12: 4.1517827e+27 | T12: =R12-S12 | U12: =IF(ABS(S12)<1E-300,"",R12/S12) | V12: 1.979361e+37 | W12: 1.6036618e+26 | X12: =V12-W12 | Y12: =IF(ABS(W12)<1E-300,"",V12/W12) | Z12: 4.948534e+35 | AA12: 1.1723894e+28 | AB12: =Z12-AA12 | AC12: =IF(ABS(AA12)<1E-300,"",Z12/AA12)
A13: 2.1 | B13: 1.848195e+37 | C13: 2.1811867e+27 | D13: =B13-C13 | E13: =IF(ABS(C13)<1E-300,"",B13/C13) | F13: 6.777509e+36 | G13: 4.2455081e+26 | H13: =F13-G13 | I13: =IF(ABS(G13)<1E-300,"",F13/G13) | J13: 6.777509e+36 | K13: -7.2335628e+26 | L13: =J13-K13 | M13: =IF(ABS(K13)<1E-300,"",J13/K13) | N13: 6.777509e+36 | O13: -7.3023305e+26 | P13: =N13-O13 | Q13: =IF(ABS(O13)<1E-300,"",N13/O13) | R13: 1.979361e+37 | S13: -1.098575e+28 | T13: =R13-S13 | U13: =IF(ABS(S13)<1E-300,"",R13/S13) | V13: 1.979361e+37 | W13: -3.5681761e+26 | X13: =V13-W13 | Y13: =IF(ABS(W13)<1E-300,"",V13/W13) | Z13: 4.948534e+35 | AA13: -6.2647047e+27 | AB13: =Z13-AA13 | AC13: =IF(ABS(AA13)<1E-300,"",Z13/AA13)
A14: 2.3 | B14: 1.848195e+37 | C14: -7.0111229e+28 | D14: =B14-C14 | E14: =IF(ABS(C14)<1E-300,"",B14/C14) | F14: 6.776426e+36 | G14: -4.6734482e+26 | H14: =F14-G14 | I14: =IF(ABS(G14)<1E-300,"",F14/G14) | J14: 6.776426e+36 | K14: 7.1215191e+28 | L14: =J14-K14 | M14: =IF(ABS(K14)<1E-300,"",J14/K14) | N14: 6.776426e+36 | O14: -8.6512525e+26 | P14: =N14-O14 | Q14: =IF(ABS(O14)<1E-300,"",N14/O14) | R14: 1.979361e+37 | S14: 2.160547e+27 | T14: =R14-S14 | U14: =IF(ABS(S14)<1E-300,"",R14/S14) | V14: 1.979361e+37 | W14: -1.4179066e+25 | X14: =V14-W14 | Y14: =IF(ABS(W14)<1E-300,"",V14/W14) | Z14: 4.948534e+35 | AA14: 8.3536809e+26 | AB14: =Z14-AA14 | AC14: =IF(ABS(AA14)<1E-300,"",Z14/AA14)
... A150: 29.5 | B150: 1.848195e+37 | C150: 4.6290447e+32 | D150: =B150-C150 | E150: =IF(ABS(C150)<1E-300,"",B150/C150) | F150: 6.7767509e+36 | G150: 4.9976492e+31 | H150: =F150-G150 | I150: =IF(ABS(G150)<1E-300,"",F150/G150) | J150: 6.7767509e+36 | K150: -2.4584931e+32 | L150: =J150-K150 | M150: =IF(ABS(K150)<1E-300,"",J150/K150) | N150: 6.7767509e+36 | O150: -2.4574276e+32 | P150: =N150-O150 | Q150: =IF(ABS(O150)<1E-300,"",N150/O150) | R150: 1.979361e+37 | S150: 0 | T150: =R150-S150 | U150: =IF(ABS(S150)<1E-300,"",R150/S150) | V150: 1.979361e+37 | W150: 0 | X150: =V150-W150 | Y150: =IF(ABS(W150)<1E-300,"",V150/W150) | Z150: 4.948534e+35 | AA150: -6.6195826e+29 | AB150: =Z150-AA150 | AC150: =IF(ABS(AA150)<1E-300,"",Z150/AA150)

Sheet Fig 10
A1: Figure 10: the warp shell's four sampled energy-condition maps, as Figure 7.
A2: r [m] | B2: Null: paper | C2: Null: ours | D2: difference (paper - ours) | E2: ratio paper / ours | F2: Weak: paper | G2: Weak: ours | H2: difference (paper - ours) | I2: ratio paper / ours | J2: Strong: paper | K2: Strong: ours | L2: difference (paper - ours) | M2: ratio paper / ours | N2: Dominant: paper | O2: Dominant: ours | P2: difference (paper - ours) | Q2: ratio paper / ours | R2: Null, consistent metric: paper | S2: Null, consistent metric: ours | T2: difference (paper - ours) | U2: ratio paper / ours | V2: Weak, consistent metric: paper | W2: Weak, consistent metric: ours | X2: difference (paper - ours) | Y2: ratio paper / ours
A3: 0.1 | B3: 1.971376e+37 | C3: -5.3737757e+27 | D3: =B3-C3 | E3: =IF(ABS(C3)<1E-300,"",B3/C3) | F3: 1.971376e+37 | G3: -5.3737757e+27 | H3: =F3-G3 | I3: =IF(ABS(G3)<1E-300,"",F3/G3) | J3: 1.979729e+37 | K3: -7.0002696e+27 | L3: =J3-K3 | M3: =IF(ABS(K3)<1E-300,"",J3/K3) | N3: 1.979729e+37 | O3: -1.0033814e+28 | P3: =N3-O3 | Q3: =IF(ABS(O3)<1E-300,"",N3/O3) | S3: -7.0002696e+27 | W3: -7.0002696e+27
A4: 0.3 | B4: 1.971376e+37 | C4: -3.0683914e+27 | D4: =B4-C4 | E4: =IF(ABS(C4)<1E-300,"",B4/C4) | F4: 1.971376e+37 | G4: -3.0683914e+27 | H4: =F4-G4 | I4: =IF(ABS(G4)<1E-300,"",F4/G4) | J4: 1.979729e+37 | K4: -4.0804882e+27 | L4: =J4-K4 | M4: =IF(ABS(K4)<1E-300,"",J4/K4) | N4: 1.979729e+37 | O4: -5.4496365e+27 | P4: =N4-O4 | Q4: =IF(ABS(O4)<1E-300,"",N4/O4) | S4: -4.0804882e+27 | W4: -4.0804882e+27
A5: 0.5 | B5: 1.971376e+37 | C5: 1.6478258e+25 | D5: =B5-C5 | E5: =IF(ABS(C5)<1E-300,"",B5/C5) | F5: 1.971376e+37 | G5: 1.6478258e+25 | H5: =F5-G5 | I5: =IF(ABS(G5)<1E-300,"",F5/G5) | J5: 1.979729e+37 | K5: 4.4186498e+26 | L5: =J5-K5 | M5: =IF(ABS(K5)<1E-300,"",J5/K5) | N5: 1.979729e+37 | O5: -3.0413978e+28 | P5: =N5-O5 | Q5: =IF(ABS(O5)<1E-300,"",N5/O5) | S5: 4.4186498e+26 | W5: 4.4186498e+26
A6: 0.7 | B6: 1.971376e+37 | C6: -1.1251325e+27 | D6: =B6-C6 | E6: =IF(ABS(C6)<1E-300,"",B6/C6) | F6: 1.971376e+37 | G6: -2.3830538e+28 | H6: =F6-G6 | I6: =IF(ABS(G6)<1E-300,"",F6/G6) | J6: 1.979729e+37 | K6: -2.6552153e+28 | L6: =J6-K6 | M6: =IF(ABS(K6)<1E-300,"",J6/K6) | N6: 1.979729e+37 | O6: -9.7673717e+28 | P6: =N6-O6 | Q6: =IF(ABS(O6)<1E-300,"",N6/O6) | S6: -2.6552153e+28 | W6: -7.055613e+28
A7: 0.9 | B7: 1.971376e+37 | C7: -1.0648513e+29 | D7: =B7-C7 | E7: =IF(ABS(C7)<1E-300,"",B7/C7) | F7: 1.971376e+37 | G7: -1.0648513e+29 | H7: =F7-G7 | I7: =IF(ABS(G7)<1E-300,"",F7/G7) | J7: 1.979729e+37 | K7: -1.7012365e+29 | L7: =J7-K7 | M7: =IF(ABS(K7)<1E-300,"",J7/K7) | N7: 1.979729e+37 | O7: -1.1513562e+29 | P7: =N7-O7 | Q7: =IF(ABS(O7)<1E-300,"",N7/O7) | S7: -1.7012365e+29 | W7: -1.7012365e+29
A8: 1.1 | B8: 1.971376e+37 | C8: -5.3290975e+28 | D8: =B8-C8 | E8: =IF(ABS(C8)<1E-300,"",B8/C8) | F8: 1.971376e+37 | G8: -5.5915654e+28 | H8: =F8-G8 | I8: =IF(ABS(G8)<1E-300,"",F8/G8) | J8: 1.979729e+37 | K8: -1.0806348e+29 | L8: =J8-K8 | M8: =IF(ABS(K8)<1E-300,"",J8/K8) | N8: 1.979729e+37 | O8: -8.126371e+28 | P8: =N8-O8 | Q8: =IF(ABS(O8)<1E-300,"",N8/O8) | S8: -1.0806348e+29 | W8: -1.1115358e+29
A9: 1.3 | B9: 1.971376e+37 | C9: -9.7031135e+27 | D9: =B9-C9 | E9: =IF(ABS(C9)<1E-300,"",B9/C9) | F9: 1.971376e+37 | G9: -1.4055882e+28 | H9: =F9-G9 | I9: =IF(ABS(G9)<1E-300,"",F9/G9) | J9: 1.979729e+37 | K9: -2.5093594e+28 | L9: =J9-K9 | M9: =IF(ABS(K9)<1E-300,"",J9/K9) | N9: 1.979729e+37 | O9: -3.0927941e+28 | P9: =N9-O9 | Q9: =IF(ABS(O9)<1E-300,"",N9/O9) | S9: -2.5093594e+28 | W9: -3.8962395e+28
A10: 1.5 | B10: 1.971376e+37 | C10: -2.7667265e+28 | D10: =B10-C10 | E10: =IF(ABS(C10)<1E-300,"",B10/C10) | F10: 1.971376e+37 | G10: -2.7667265e+28 | H10: =F10-G10 | I10: =IF(ABS(G10)<1E-300,"",F10/G10) | J10: 1.979729e+37 | K10: -4.2406136e+28 | L10: =J10-K10 | M10: =IF(ABS(K10)<1E-300,"",J10/K10) | N10: 1.979729e+37 | O10: -7.6254745e+28 | P10: =N10-O10 | Q10: =IF(ABS(O10)<1E-300,"",N10/O10) | S10: -4.2406136e+28 | W10: -4.3949379e+28
A11: 1.7 | B11: 1.971376e+37 | C11: -3.3268012e+28 | D11: =B11-C11 | E11: =IF(ABS(C11)<1E-300,"",B11/C11) | F11: 1.971376e+37 | G11: -3.3268012e+28 | H11: =F11-G11 | I11: =IF(ABS(G11)<1E-300,"",F11/G11) | J11: 1.979729e+37 | K11: -6.2051727e+28 | L11: =J11-K11 | M11: =IF(ABS(K11)<1E-300,"",J11/K11) | N11: 1.979729e+37 | O11: -4.731864e+28 | P11: =N11-O11 | Q11: =IF(ABS(O11)<1E-300,"",N11/O11) | S11: -3.5042247e+28 | W11: -3.5042247e+28
A12: 1.9 | B12: 1.971376e+37 | C12: -1.0190341e+28 | D12: =B12-C12 | E12: =IF(ABS(C12)<1E-300,"",B12/C12) | F12: 1.971376e+37 | G12: -1.2165798e+28 | H12: =F12-G12 | I12: =IF(ABS(G12)<1E-300,"",F12/G12) | J12: 1.979729e+37 | K12: -2.2553317e+28 | L12: =J12-K12 | M12: =IF(ABS(K12)<1E-300,"",J12/K12) | N12: 1.979729e+37 | O12: 1.1107205e+28 | P12: =N12-O12 | Q12: =IF(ABS(O12)<1E-300,"",N12/O12) | S12: -2.2553317e+28 | W12: -3.5336042e+28
A13: 2.1 | B13: 1.971376e+37 | C13: -8.1062361e+27 | D13: =B13-C13 | E13: =IF(ABS(C13)<1E-300,"",B13/C13) | F13: 1.971376e+37 | G13: -8.1062361e+27 | H13: =F13-G13 | I13: =IF(ABS(G13)<1E-300,"",F13/G13) | J13: 1.979729e+37 | K13: -1.1478413e+28 | L13: =J13-K13 | M13: =IF(ABS(K13)<1E-300,"",J13/K13) | N13: 1.979729e+37 | O13: -1.211751e+28 | P13: =N13-O13 | Q13: =IF(ABS(O13)<1E-300,"",N13/O13) | S13: -1.1478413e+28 | W13: -1.1478413e+28
A14: 2.3 | B14: 1.971376e+37 | C14: -1.2267299e+28 | D14: =B14-C14 | E14: =IF(ABS(C14)<1E-300,"",B14/C14) | F14: 1.971376e+37 | G14: -2.3526349e+28 | H14: =F14-G14 | I14: =IF(ABS(G14)<1E-300,"",F14/G14) | J14: 1.979729e+37 | K14: -3.5515485e+28 | L14: =J14-K14 | M14: =IF(ABS(K14)<1E-300,"",J14/K14) | N14: 1.979729e+37 | O14: -1.8644771e+28 | P14: =N14-O14 | Q14: =IF(ABS(O14)<1E-300,"",N14/O14) | S14: -3.5515485e+28 | W14: -7.0111229e+28
